Workbook

Sheet Help
A1: Inventory – Castlevania: Belmont's Curse (APWorld cvbc)
A3: How to fill
A4: • Every Item name and Location name must be UNIQUE: they are used as-is in the Python files.
A5: • Location naming convention: « Area abbreviation - Sub-area : Description » (e.g. PS - Sewer Reservoir : Gold Chest).
A6: • Several rewards from the same event = several locations: add a suffix (e.g. « … : Leon Belmont Absorbed - Tarot », « - Key », « - Skill »).
A7: • Prerequisites: write exact item names, separated by « AND » / « OR » (e.g. Double Jump AND Tarot : The Shadow).
A8: • Columns marked ▼ have a dropdown list.
A9: • Items › Quantity must be a number: it feeds the Total sheet, which computes itself.
A10: • « X » = not applicable.
A12: IDs
A13: • « AP ID »: ID chosen by us for Archipelago, inside the category range (see ID Range sheet). Never change it once released.
A14: • ONE AP ID per item NAME (all copies of « Brave Heart Fragment » share the same ID), ONE AP ID per LOCATION.
... A40: • Jeanne d'Arc and Aliénor d'Aquitaine keep their French names on purpose (client and AP messages). Please respect this little quirk of mine

Sheet Total
A1: Computed automatically from the Items and Locations sheets.
A2: Category | B2: Items (total quantity) | C2: Locations | D2: Difference (locations − items)
A3: Relic | B3: =SUMIFS(Items!$E$3:$E$399,Items!$B$3:$B$399,A3) -> 42 | C3: =COUNTIF(Locations!$C$3:$C$498,A3) -> 42 | D3: =C3-B3 -> 0
A4: Weapon | B4: =SUMIFS(Items!$E$3:$E$399,Items!$B$3:$B$399,A4) -> 28 | C4: =COUNTIF(Locations!$C$3:$C$498,A4) -> 28 | D4: =C4-B4 -> 0
A5: Clue | B5: =SUMIFS(Items!$E$3:$E$399,Items!$B$3:$B$399,A5) -> 40 | C5: =COUNTIF(Locations!$C$3:$C$498,A5) -> 40 | D5: =C5-B5 -> 0
A6: Tarot Cards | B6: =SUMIFS(Items!$E$3:$E$399,Items!$B$3:$B$399,A6) -> 16 | C6: =COUNTIF(Locations!$C$3:$C$498,A6) -> 16 | D6: =C6-B6 -> 0
A7: Augmentation | B7: =SUMIFS(Items!$E$3:$E$399,Items!$B$3:$B$399,A7) -> 76 | C7: =COUNTIF(Locations!$C$3:$C$498,A7) -> 76 | D7: =C7-B7 -> 0
A8: Work of Mercy upgrade | B8: =SUMIFS(Items!$E$3:$E$399,Items!$B$3:$B$399,A8) -> 43 | C8: =COUNTIF(Locations!$C$3:$C$498,A8) -> 43 | D8: =C8-B8 -> 0
A9: Key Item / Skill | B9: =SUMIFS(Items!$E$3:$E$399,Items!$B$3:$B$399,A9) -> 18 | C9: =COUNTIF(Locations!$C$3:$C$498,A9) -> 18 | D9: =C9-B9 -> 0
A10: EXP Statue | B10: =SUMIFS(Items!$E$3:$E$399,Items!$B$3:$B$399,A10) -> 147 | C10: =COUNTIF(Locations!$C$3:$C$498,A10) -> 147 | D10: =C10-B10 -> 0
A11: Total | B11: =SUM(B3:B10) -> 410 | C11: =SUM(C3:C10) -> 410 | D11: =SUM(D3:D10) -> 0

Sheet Items
A1: One item per row. HP/MP augmentations: one row « … Heart Fragment » with the total quantity. Quantity 0 = only created by an option.
A2: Item name | B2: Category ▼ | C2: Progressive group (weapons) | D2: Tier | E2: Quantity | F2: Classification ▼ | G2: Vanilla location | H2: Required for (ending / area / interaction / Work of Mercy) | I2: AP ID | J2: Internal ID (game) | K2: Notes
A3: Abyssal Eye | B3: Relic | E3: 1 | F3: useful | G3: HIC - Cemetery Entrance : Silver Chest | H3: X | I3: 7001001
A4: Banshee's Wall | B4: Relic | E4: 1 | F4: useful | G4: MH - Servant's Quarters : Silver Chest | H4: X | I4: 7001002
A5: Beelzebub's Seal | B5: Relic | E5: 1 | F5: useful | G5: ND - Chapel of Patience : Silver Chest | H5: X | I5: 7001003
A6: Blackened Heart | B6: Relic | E6: 1 | F6: useful | G6: MH - Abandoned Staircase : Silver Chest | H6: X | I6: 7001004
A7: Blood Vial | B7: Relic | E7: 1 | F7: useful | G7: MH - Archives : Silver Chest | H7: X | I7: 7001005
A8: Crypt Key | B8: Relic | E8: 1 | F8: useful | G8: PS - Seer's Hovel : Silver Chest | H8: X | I8: 7001006
A9: Crystallized Blood | B9: Relic | E9: 1 | F9: useful | G9: HoM - Dead-end Tower : Silver Chest | H9: X | I9: 7001007
A10: Cursed Coin | B10: Relic | E10: 1 | F10: useful | G10: MH - Wine Cellar : Silver Chest | H10: X | I10: 7001008
A11: Dark Sigil | B11: Relic | E11: 1 | F11: useful | G11: PS - Street of the Tomb Masons : Silver Chest | H11: X | I11: 7001009
A12: Dusk Amulet | B12: Relic | E12: 1 | F12: useful | G12: HoM - Delived Level : Silver Chest | H12: X | I12: 7001010
A13: Ebony Claw | B13: Relic | E13: 1 | F13: useful | G13: CoP - Throat of Hell : Silver Chest | H13: X | I13: 7001011
A14: Eldritch Talisman | B14: Relic | E14: 1 | F14: useful | G14: ND - East Gallery : Silver Chest | H14: X | I14: 7001012
... A43: Wraith's Tear | B43: Relic | E43: 1 | F43: useful | G43: L - Study Room : Silver Chest | H43: X | I43: 7001041
A44: Family's Grave | B44: Relic | E44: 1 | F44: useful | G44: PS - Bank of the River Seine : Starting Relic (DLC) | H44: X | I44: 7001042 | K44: DLC item – not obtainable without the DLC
A45: Whip | B45: Weapon | C45: Whip | D45: 1 | E45: 1 | F45: progression | G45: CoP - Hall of the Fallen Angels : Gold Chest | H45: Hall of Mirrors seals (OR Double Jump OR Aerial Rush) | I45: 7002001
A46: Thorn Whip | B46: Weapon | C46: Whip | D46: 2 | E46: 1 | F46: progression | G46: L - Fine Arts Shelves : Gold Chest | H46: Hall of Mirrors seals (OR Double Jump OR Aerial Rush) | I46: 7002002
A47: Morning Star | B47: Weapon | C47: Whip | D47: 3 | E47: 1 | F47: progression | G47: MH - Inner Courtyard : Gold Chest | H47: Hall of Mirrors seals (OR Double Jump OR Aerial Rush) | I47: 7002003
A48: Vampire Killer | B48: Weapon | C48: Whip | D48: 4 | E48: 1 | F48: progression | G48: ND - Deacon's Quarter : Trevor Belmont | H48: Hall of Mirrors seals (OR Double Jump OR Aerial Rush) | I48: 7002004
A49: Longsword | B49: Weapon | C49: OHSword | D49: 1 | E49: 1 | F49: useful | G49: PS - Bank of the River Seine : Starting Weapon | H49: X | I49: 7002005 | K49: Starting weapon
A50: Bastard Sword | B50: Weapon | C50: OHSword | D50: 2 | E50: 1 | F50: useful | G50: PS - Justice District Sewers : Gold Chest | H50: X | I50: 7002006
A51: Joyeuse | B51: Weapon | C51: OHSword | D51: 3 | E51: 1 | F51: useful | G51: ND - Path of the Penitent : Gold Chest | H51: X | I51: 7002007
A52: Valmanway | B52: Weapon | C52: OHSword | D52: 4 | E52: 1 | F52: useful | G52: PS - Palace of Justice : Saint Louis | H52: X | I52: 7002008
A53: Burnt Sword of Fierbois | B53: Weapon | C53: THSword | D53: 1 | E53: 1 | F53: useful | G53: PS - Roof of the Tower : Jeanne d'Arc Defeated | H53: X | I53: 7002009
A54: Claymore | B54: Weapon | C54: THSword | D54: 2 | E54: 1 | F54: useful | G54: CT - The Way of the Fist : Gold Chest | H54: X | I54: 7002010
A55: Durandal | B55: Weapon | C55: THSword | D55: 3 | E55: 1 | F55: useful | G55: L - Lisa's Laboratory : Gold Chest | H55: X | I55: 7002011
A56: Excalibur | B56: Weapon | C56: THSword | D56: 4 | E56: 1 | F56: useful | G56: ND - Chapel : Arthur Defeated | H56: X | I56: 7002012
A57: Pair of Longswords | B57: Weapon | C57: Dual Blades | D57: 1 | E57: 1 | F57: useful | G57: CoP - Crossroads of the Dead : Gold Chest | H57: X | I57: 7002013
A58: Rapiers | B58: Weapon | C58: Dual Blades | D58: 2 | E58: 1 | F58: useful | G58: MH - Watch Tower : Gold Chest | H58: X | I58: 7002014
A59: Almace and Hauteclaire | B59: Weapon | C59: Dual Blades | D59: 3 | E59: 1 | F59: useful | G59: HIC - Flooded Crypt : Gold Chest | H59: X | I59: 7002015
A60: War and Famine | B60: Weapon | C60: Dual Blades | D60: 4 | E60: 1 | F60: useful | G60: ND - Great Organ Room : Unique Reward | H60: X | I60: 7002016
A61: Lance | B61: Weapon | C61: Spear | D61: 1 | E61: 1 | F61: useful | G61: HIC - Fountain of the Innocents : Gold Chest | H61: X | I61: 7002017
... A72: Alucard's Sword and Shield | B72: Weapon | C72: Sword and Shield | D72: 4 | E72: 1 | F72: useful | G72: MH - Alucard's Tower : Unique Reward | H72: X | I72: 7002028
A73: Progressive Whip | B73: Weapon | C73: Whip | E73: 0 | F73: progression | G73: X | H73: Hall of Mirrors seals (OR Double Jump OR Aerial Rush) | I73: 7002029 | K73: Only with « Progressive Weapons »: replaces the 4 weapons of the group
A74: Progressive OHSword | B74: Weapon | C74: OHSword | E74: 0 | F74: useful | G74: X | H74: X | I74: 7002030 | K74: Only with « Progressive Weapons »: replaces the 4 weapons of the group
A75: Progressive THSword | B75: Weapon | C75: THSword | E75: 0 | F75: useful | G75: X | H75: X | I75: 7002031 | K75: Only with « Progressive Weapons »: replaces the 4 weapons of the group
A76: Progressive Dual Blades | B76: Weapon | C76: Dual Blades | E76: 0 | F76: useful | G76: X | H76: X | I76: 7002032 | K76: Only with « Progressive Weapons »: replaces the 4 weapons of the group
A77: Progressive Spear | B77: Weapon | C77: Spear | E77: 0 | F77: useful | G77: X | H77: X | I77: 7002033 | K77: Only with « Progressive Weapons »: replaces the 4 weapons of the group
A78: Progressive Fists | B78: Weapon | C78: Fists | E78: 0 | F78: useful | G78: X | H78: X | I78: 7002034 | K78: Only with « Progressive Weapons »: replaces the 4 weapons of the group
...

Sheet Locations
A1: One location = one check. The vanilla category tells which locations stay locked to their vanilla item when that category is not randomized.
A2: Location name | B2: Check type ▼ | C2: Vanilla category ▼ | D2: Area | E2: Sub-area | F2: Vanilla item | G2: Access prerequisites | H2: Missable? ▼ | I2: AP ID | J2: Internal ID (game) | K2: Notes | L2: Logic region
A3: HIC - Cemetery Entrance : Silver Chest | B3: Silver Chest | C3: Relic | D3: Holy Innocents' Cemetery | E3: Cemetery Entrance | F3: Abyssal Eye | G3: Arcane Whip AND Holy Light | I3: 7101001 | K3: Other xlsx #26 | L3: Holy Innocents' Cemetery
A4: MH - Servant's Quarters : Silver Chest | B4: Silver Chest | C4: Relic | D4: Main Hall | E4: Servant's Quarters | F4: Banshee's Wall | G4: Arcane Whip AND Smash | I4: 7101002 | K4: Other xlsx #80 | L4: Main Hall
A5: ND - Chapel of Patience : Silver Chest | B5: Silver Chest | C5: Relic | D5: Notre-Dame | E5: Chapel of Patience | F5: Beelzebub's Seal | G5: Nothing extra | I5: 7101003 | K5: Other xlsx #59 | L5: Notre-Dame
A6: MH - Abandoned Staircase : Silver Chest | B6: Silver Chest | C6: Relic | D6: Main Hall | E6: Abandoned Staircase | F6: Blackened Heart | G6: Aerial Rush AND Arcane Whip AND Double Jump | I6: 7101004 | K6: Other xlsx #82 | L6: Main Hall
A7: MH - Archives : Silver Chest | B7: Silver Chest | C7: Relic | D7: Main Hall | E7: Archives | F7: Blood Vial | G7: Arcane Whip AND Double Jump | I7: 7101005 | K7: Other xlsx #81 | L7: Main Hall
A8: PS - Seer's Hovel : Silver Chest | B8: Silver Chest | C8: Relic | D8: Paris Streets | E8: Seer's Hovel | F8: Crypt Key | G8: Arcane Whip | I8: 7101006 | K8: Other xlsx #10 | L8: Paris Streets
A9: HoM - Dead-end Tower : Silver Chest | B9: Silver Chest | C9: Relic | D9: Hall of Mirrors | E9: Dead-end Tower | F9: Crystallized Blood | G9: Nothing extra | I9: 7101007 | K9: Other xlsx #133 | L9: Hall of Mirrors
A10: MH - Wine Cellar : Silver Chest | B10: Silver Chest | C10: Relic | D10: Main Hall | E10: Wine Cellar | F10: Cursed Coin | G10: Arcane Whip | I10: 7101008 | K10: Other xlsx #86 | L10: Main Hall
A11: PS - Ruined Market : Silver Chest | B11: Silver Chest | C11: Relic | D11: Paris Streets | E11: Ruined Market | F11: Dark Sigil | G11: Arcane Whip AND Double Jump | I11: 7101009 | K11: Other xlsx #9 | L11: Paris Streets
A12: HoM - Delived Level : Silver Chest | B12: Silver Chest | C12: Relic | D12: Hall of Mirrors | E12: Delived Level | F12: Dusk Amulet | G12: Smash | I12: 7101010 | K12: Other xlsx #132 | L12: Hall of Mirrors
A13: CoP - Throat of Hell : Silver Chest | B13: Silver Chest | C13: Relic | D13: Catacombs of Paris | E13: Throat of Hell | F13: Ebony Claw | G13: Arcane Whip AND Holy Light AND Smash | I13: 7101011 | K13: Other xlsx #40 | L13: Catacombs of Paris
A14: ND - East Gallery : Silver Chest | B14: Silver Chest | C14: Relic | D14: Notre-Dame | E14: East Gallery | F14: Eldritch Talisman | G14: Nothing extra | I14: 7101012 | K14: Other xlsx #63 | L14: Notre-Dame
... A107: HoM - Looping Hallways : Spy Statue | B107: Statue | C107: Clue | D107: Hall of Mirrors | E107: Looping Hallways | F107: The Sage Second Clue | G107: Nothing extra | I107: 7103038 | K107: Other xlsx candidates: #343 « A Sketch from Talos » (Nothing extra); #341 « Eleanor Flees to the Cemetary » (Nothing extra); #342 « Kneeling is the Way » (Nothing extra); #344 « The Reflection Deceives » (Nothing extra) | L107: Hall of Mirrors
A108: CT - Builder's Bureau : Note | B108: Note / Stele | C108: Clue | D108: Clock Tower | E108: Builder's Bureau | F108: The Sage Third Clue | G108: Nothing extra | I108: 7103039 | K108: No same-area match in the other xlsx (they place this card's clues in: Hall of Mirrors)
A109: HoM - Steps of Misdirection : Spy Statue | B109: Statue | C109: Clue | D109: Hall of Mirrors | E109: Steps of Misdirection | F109: The Sage Fourth Clue | G109: Nothing extra | I109: 7103040 | K109: Other xlsx candidates: #343 « A Sketch from Talos » (Nothing extra); #341 « Eleanor Flees to the Cemetary » (Nothing extra); #342 « Kneeling is the Way » (Nothing extra); #344 « The Reflection Deceives » (Nothing extra) | L109: Hall of Mirrors
A110: ND - Gallery of the Four Virtues : Doppelganger Absorbed | B110: Absorption (Boss/NPC) | C110: Tarot Cards | D110: Notre-Dame | E110: Gallery of the Four Virtues | F110: Tarot : The Self | G110: Arcane Whip AND Holy Light AND Smash AND Aerial Rush AND Double Jump AND Tarot : The Judge AND Tarot : The Sage AND Tarot : The Whisperer AND Tarot : The Warrior | I110: 7104002 | K110: Other xlsx #355: Four virtue trials need Chains of Justice, Infernal Pyre, Mirror Walk, Freezing Path; then The Self. Absorbing her arcana (Absolution, game id RageIncarnation) normally turns Cursed Flame into Absolution, the true-ending spell (Charles). | L110: Notre-Dame
A111: PS - Gate of the Catacombs : Leon Belmont Absorbed - Tarot | B111: Absorption (Boss/NPC) | C111: Tarot Cards | D111: Paris Streets | E111: Gate of the Catacombs | F111: Tarot : The Fallen | G111: Nothing extra | I111: 7104003 | K111: Other xlsx #146 | Leon Boss Loot 1/2: which of Tarot/Key is 1 or 2 not specified | L111: Paris Streets (Start)
A112: PS - Roof of the Tower : Jeanne d'Arc Absorbed - Tarot | B112: Absorption (Boss/NPC) | C112: Tarot Cards | D112: Paris Streets | E112: Roof of the Tower | F112: Tarot : The Warrior | G112: Nothing extra | I112: 7104004 | K112: Other xlsx #149 | Joan Boss Loot 1/2: Tarot/Key order not specified | L112: Paris Streets
A113: HIC - Ossuary of the Innocents : Medusa Absorbed - Tarot | B113: Absorption (Boss/NPC) | C113: Tarot Cards | D113: Holy Innocents' Cemetery | E113: Ossuary of the Innocents | F113: Tarot : The Prophetess | G113: Nothing extra | I113: 7104005 | K113: Other xlsx #152 | Medusa Boss Loot 1/2: Tarot/Key order not specified | L113: Holy Innocents' Cemetery
A114: CT - Throne of the Builder : Talos Absorbed - Tarot | B114: Absorption (Boss/NPC) | C114: Tarot Cards | D114: Clock Tower | E114: Throne of the Builder | F114: Tarot : The Builder | G114: Nothing extra | I114: 7104006 | K114: Other xlsx #158 | L114: Clock Tower
A115: MH - Brauner's Atelier : Brauner Absorbed | B115: Absorption (Boss/NPC) | C115: Tarot Cards | D115: Main Hall | E115: Brauner's Atelier | F115: Tarot : The Artist | G115: Nothing extra | I115: 7104007 | K115: Other xlsx #154 | Other xlsx lists TWO Brauner rewards (#154, #155 Boss Loot 1/2): what is the second one? | L115: Main Hall
A116: L - Observatory : Carmilla Absorbed - Tarot | B116: Absorption (Boss/NPC) | C116: Tarot Cards | D116: Library | E116: Observatory | F116: Tarot : The Occultist | G116: Nothing extra | I116: 7104008 | K116: Other xlsx #156 | L116: Library
A117: ND - Choir : Death Almost Absorbed - Tarot | B117: Absorption (Boss/NPC) | C117: Tarot Cards | D117: Notre-Dame | E117: Choir | F117: Tarot : The Shadow | G117: Nothing extra | I117: 7104009 | K117: Other xlsx #160 | L117: Notre-Dame
A118: CoP - Mammon's Lair : Mammon Absorbed | B118: Absorption (Boss/NPC) | C118: Tarot Cards | D118: Catacombs of Paris | E118: Mammon's Lair | F118: Tarot : The Miser | G118: Nothing extra | I118: 7104010 | K118: Other xlsx #359: Mammon's arcana (Wheel of Chaos), absorbed from BossLoot | L118: Mammon's Lair
A119: Ferryman's Wharf : Ferryman's Gift Absorbed | B119: Absorption (Boss/NPC) | C119: Tarot Cards | F119: Tarot : The Whisperer | G119: Ferryman's Obol | I119: 7104011 | K119: Other xlsx #162 | Other xlsx hangs the Ferryman on the Catacombs region; in-game he appears in every area | L119: Catacombs of Paris
A120: CT - Heart of the Clock : Isaac Absorbed | B120: Absorption (Boss/NPC) | C120: Tarot Cards | D120: Clock Tower | E120: Heart of the Clock | F120: Tarot : The Zealot | G120: Nothing extra | I120: 7104012 | K120: Other xlsx #357 | L120: Clock Tower (Upper)
A121: HoM - Belmont Manor : Succubus Absorbed | B121: Absorption (Boss/NPC) | C121: Tarot Cards | D121: Hall of Mirrors | E121: Belmont Manor | F121: Tarot : The Temptress | G121: Nothing extra | I121: 7104013 | J121: SuccubusAgnes_Defeated_ID | K121: Other xlsx #358: Succubus (Agnes) drops her arcana only (Charles's log: INV_ADD LifeDrain from BossLoot; key SuccubusAgnes_Defeated_ID) | L121: Hall of Mirrors
A122: ND - Chapel : Arthur Absorbed | B122: Absorption (Boss/NPC) | C122: Tarot Cards | D122: Notre-Dame | E122: Chapel | F122: Tarot : The Brittle King | G122: Tarot : The Builder | I122: 7104014 | K122: Other xlsx #76: Arthur only fights with Fist of Talos (The Builder's spell) equipped (Charles). | Arthur only fights with Fist of Talos (Tarot : The Builder) equipped | L122: Notre-Dame
A123: PS - Palace of Justice : Saint Louis Absorbed | B123: Absorption (Boss/NPC) | C123: Tarot Cards | D123: Paris Streets | E123: Palace of Justice | F123: Tarot : The Judge | G123: 24 Heart Fragments (Brave Heart Fragment + Wise Heart Fragment combined) | I123: 7104015 | J123: Street_Poor_Justice_Louis_Intro (cutscene) | K123: Other xlsx #354: The Judge's scales need max HP + max MP >= 320 (Charles). Start 100 HP + 100 MP; each full heart (4 fragments) gives +20 HP or MP; levels only give ATK/DEF. So 6 full upgrades, Health and Mana combined. The arcana is absorbed in the cutscene Street_Poor_Justice_Louis_Intro (client 0.5.6 never skips it). | Not a boss fight (scripted interaction). Other xlsx places it in the Notre-Dame logic region – to verify | L123: Paris Streets
A124: HIC - Mausoleum of the Queens : Aliénor Absorbed | B124: Absorption (Boss/NPC) | C124: Tarot Cards | D124: Holy Innocents' Cemetery | E124: Mausoleum of the Queens | F124: Tarot : The Sage | G124: Nothing extra | I124: 7104016 | L124: Holy Innocents' Cemetery
A125: PS - Gate of the Catacombs : Leon Belmont Absorbed - Key | B125: Absorption (Boss/NPC) | C125: Key Item / Skill | D125: Paris Streets | E125: Gate of the Catacombs | F125: The Fallen's Key | G125: Nothing extra | I125: 7107001 | K125: Other xlsx #147 | L125: Paris Streets (Start)
A126: PS - Roof of the Tower : Jeanne d'Arc Absorbed - Key | B126: Absorption (Boss/NPC) | C126: Key Item / Skill | D126: Paris Streets | E126: Roof of the Tower | F126: The Warrior's Key | G126: Nothing extra | I126: 7107002 | K126: Other xlsx #150 | L126: Paris Streets
A127: HIC - Ossuary of the Innocents : Medusa Absorbed - Key | B127: Absorption (Boss/NPC) | C127: Key Item / Skill | D127: Holy Innocents' Cemetery | E127: Ossuary of the Innocents | F127: The Prophetess's Key | G127: Nothing extra | I127: 7107003 | K127: Other xlsx #153 | L127: Holy Innocents' Cemetery
A128: L - Observatory : Carmilla Defeated | B128: Scripted Event | C128: Key Item / Skill | D128: Library | E128: Observatory | F128: Brauner's Paintbrush | G128: Nothing extra | I128: 7107004 | J128: LdBrick_StateMachine_Paintbrush | K128: Other xlsx #111: Carmilla's chest gives Brauner's Paintbrush. 0.5.1 removed the duplicate location 112 (LdBrick_StateMachine_Paintbrush, same pickup); the client also sends 112 for older seeds. | Carmilla's chest = Brauner's Paintbrush; 2nd trigger for the same pickup (duplicate removed in the other xlsx) | L128: Library
A129: CoP - Mammon's Lair : Mammon Defeated | B129: Scripted Event | C129: Key Item / Skill | D129: Catacombs of Paris | E129: Mammon's Lair | F129: Ferryman's Obol | G129: Nothing extra | I129: 7107005 | J129: LdBrick_StateMachine_FerrymanObols | K129: Other xlsx #53: Mammon's chest = the Ferryman's Obol (F9: Items 1/1). 0.5.11 removed duplicate 54 (LdBrick_StateMachine_FerrymanObols); the client also sends 54 for older seeds. | Mammon's chest = Ferryman's Obol; the game has a 2nd trigger for the same pickup (other xlsx removed it as a duplicate location) | L129: Mammon's Lair
A130: PS - Gate of the Catacombs : Leon Belmont Absorbed - Skill | B130: Scripted Event | C130: Key Item / Skill | D130: Paris Streets | E130: Gate of the Catacombs | F130: Arcane Whip | G130: Nothing extra | I130: 7107006 | K130: Other xlsx #148 | L130: Paris Streets (Start)
A131: PS - Roof of the Tower : Jeanne d'Arc Absorbed - Skill | B131: Scripted Event | C131: Key Item / Skill | D131: Paris Streets | E131: Roof of the Tower | F131: Holy Light | G131: Nothing extra | I131: 7107007 | K131: Other xlsx #151 | L131: Paris Streets
A132: L - Observatory : Carmilla Absorbed - Skill | B132: Scripted Event | C132: Key Item / Skill | D132: Library | E132: Observatory | F132: Aerial Rush | G132: Nothing extra | I132: 7107008 | K132: Other xlsx #157 | L132: Library
...

Sheet Areas
A1: One row per connection (logic regions, from the other xlsx). One-way passage: write « Impossible » in the blocked direction. B → A left blank = not verified.
A2: Region (Area - Sub-area) | B2: Area | C2: Sub-area | D2: Connected to | E2: Prerequisites A → B | F2: Prerequisites B → A | G2: Save point? ▼ | H2: Notes
A3: Menu | B3: Menu | D3: Paris Streets (Start) | E3: New game | H3: Logic root
A4: Paris Streets (Start) | B4: Paris Streets | C4: (Start) | D4: Paris Streets | E4: Arcane Whip OR Double Jump
A5: Paris Streets | B5: Paris Streets | D5: Holy Innocents' Cemetery | E5: Arcane Whip
A6: Paris Streets | B6: Paris Streets | D6: Catacombs of Paris (Entrance) | E6: The Fallen's Key AND The Warrior's Key AND The Prophetess's Key | H6: Three-gem door in Leon's boss room (Gate of the Catacombs)
A7: Catacombs of Paris (Entrance) | B7: Catacombs of Paris | C7: (Entrance) | D7: Catacombs of Paris | E7: Arcane Whip AND Holy Light
A8: Catacombs of Paris | B8: Catacombs of Paris | D8: Mammon's Lair | E8: Oozing Eye AND Trembling Eye AND Thrilling Eye | H8: (all three equipped)
A9: Catacombs of Paris | B9: Catacombs of Paris | D9: Ferryman's Wharf | E9: Ferryman's Obol | H9: The Ferryman appears in every area; the other xlsx hangs him on the Catacombs
A10: Paris Streets | B10: Paris Streets | D10: Main Hall | E10: Arcane Whip AND The Shadow Confronted | H10: East Streets path to the castle; the Catacombs are not on the way
A11: Main Hall | B11: Main Hall | D11: Library | E11: Nothing extra
A12: Main Hall | B12: Main Hall | D12: Clock Tower | E12: Nothing extra
A13: Clock Tower | B13: Clock Tower | D13: Clock Tower (Upper) | E13: Tarot : The Shadow AND Arcane Whip AND Double Jump AND Smash AND Aerial Rush | H13: The Shadow's spell (Soul Harvest) disarms the Death Trap
A14: Main Hall | B14: Main Hall | D14: Notre-Dame | E14: Brauner's Paintbrush AND Tarot : The Artist AND Arcane Whip AND Holy Light AND Smash AND Aerial Rush | H14: Masterpiece = Tarot : The Artist's spell
A15: Main Hall | B15: Main Hall | D15: Hall of Mirrors | E15: Mirror Kneel AND Brauner's Paintbrush AND Tarot : The Artist AND Arcane Whip AND Holy Light AND Smash AND Aerial Rush AND (Double Jump OR Aerial Rush OR Whip OR Thorn Whip OR Morning Star OR Vampire Killer) | H15: The movement/whip part breaks the 4 seals
A16: Clock Tower | B16: Clock Tower | D16: Master's Quarter (Bad Ending) | E16: Arcane Whip AND Holy Light | H16: Reached WITHOUT disarming the Death Trap → Bad Ending
A17: Clock Tower (Upper) | B17: Clock Tower | C17: (Upper) | D17: Master's Quarter | E17: Nothing extra | H17: Dracula → Neutral / True Ending
A18: Menu | B18: Menu | D18: Works of Mercy (virtual) | E18: Nothing extra | H18: Virtual region for the 44 Work of Mercy checks; each location needs its own card

Sheet Boss
A1: The exit ability will block the room in the logic AND physically in the client (anti-softlock).
A2: Boss / NPC | B2: Room | C2: Region | D2: Prerequisites to ENTER | E2: Ability required to LEAVE | F2: Vanilla reward | G2: Absorbable (card)? ▼ | H2: Linked to an ending? ▼ | I2: Notes
A3: Leon Belmont | B3: Gate of the Catacombs | C3: PS - Gate of the Catacombs | D3: X | E3: Arcane Whip | F3: Tarot : The Fallen AND The Fallen's Key | G3: Yes | H3: No
A4: Jeanne d'Arc 1 | B4: Roof of the Tower | C4: PS - Roof of the Tower | D4: Arcane Whip | E4: Holy Light | F4: Tarot : The Warrior AND The Warrior's Key | G4: Yes | H4: Yes
A5: Medusa | B5: Ossuary of the Innocents | C5: HIC - Ossuary of the Innocents | D5: Arcane Whip AND Holy Light | E5: X | F5: Tarot : The Prophetess AND The Prophetess's Key | G5: Yes | H5: No
A6: Death 1 | B6: Altar of Bones | C6: CoP - Altar of Bones | D6: Arcane Whip AND Holy Light | E6: X | F6: The Shadow Confronted | G6: No | H6: No | I6: Flag DeathCatacombs_Defeated_ID; opens the path to the Main Hall (other xlsx)
A7: Isaac 1 | B7: Castle Drawbridge | C7: MH - Castle Drawbridge | D7: Arcane Whip AND Holy Light | E7: X | F7: X | G7: No | H7: No | I7: Castle Drawbridge: Main Hall access (Arcane Whip AND The Shadow Confronted) per the other xlsx – to verify
A8: Carmilla | B8: Observatory | C8: L - Observatory | D8: Arcane Whip AND Holy Light AND The Shadow Confronted | E8: Aerial Rush | F8: Tarot : The Occultist | G8: Yes | H8: No
A9: Talos | B9: Throne of the Builder | C9: CT - Throne of the Builder | D9: Arcane Whip AND Holy Light AND The Shadow Confronted | E9: Smash | F9: Tarot : The Builder | G9: Yes | H9: No
A10: Brauner (NPC) | B10: Brauner's Atelier | C10: MH - Brauner's Atelier | D10: Arcane Whip AND Holy Light AND Smash AND The Shadow Confronted | E10: X | F10: Tarot : The Artist | G10: Yes | H10: No
A11: Saint Louis (NPC) | B11: Palace of Justice | C11: PS - Palace of Justice | D11: Arcane Whip AND Holy Light AND >= 320 HP + MP (= 24 Heart Fragments, Brave + Wise combined) | E11: X | F11: Tarot : The Judge AND OHSword : Valmanway | G11: Yes | H11: Yes | I11: Start 100 HP + 100 MP, +20 per full heart (4 fragments)
A12: Mammon | B12: Mammon's Lair | C12: CoP - Mammon's Lair | D12: Oozing Eye AND Trembling Eye AND Thrilling Eye (equipped) AND Catacombs access (3 keys AND Arcane Whip AND Holy Light) | E12: X | F12: Tarot : The Miser | G12: Yes | H12: No
A13: The Ferryman (NPC) | B13: Ferryman's Wharf | C13: Every Area | D13: Ferryman's Obol | E13: X | F13: Tarot : The Whisperer | G13: Yes | H13: Yes | I13: Other xlsx places his reward in the Catacombs region
A14: Arthur | B14: Chapel | C14: ND - Chapel | D14: Arcane Whip AND Holy Light AND Aerial Rush AND Smash AND The Shadow Confronted AND Brauner's Paintbrush AND Tarot : The Artist AND Tarot : The Builder (Fist of Talos equipped) | E14: X | F14: Tarot : The Brittle King AND THSword : Excalibur | G14: Yes | H14: No
A15: Succubus | B15: Belmont Manor | C15: HoM - Belmont Manor | D15: Arcane Whip AND Holy Light AND Aerial Rush AND Smash AND The Shadow Confronted AND Brauner's Paintbrush AND Tarot : The Artist AND Mirror Kneel AND (Double Jump OR Aerial Rush OR a whip) | E15: X | F15: Tarot : The Temptress | G15: Yes | H15: No
A16: Death 2 | B16: Choir | C16: ND - Choir | D16: Arcane Whip AND Holy Light AND Aerial Rush AND Smash AND The Shadow Confronted AND Brauner's Paintbrush AND Tarot : The Artist | E16: Double Jump | F16: Tarot : The Shadow | G16: Yes | H16: Yes
A17: Aliénor d'Aquitaine (NPC) | B17: Mausoleum of the Queens | C17: HIC - Mausoleum of the Queens | D17: Arcane Whip AND Holy Light AND Aerial Rush AND Smash AND Double Jump | E17: X | F17: Tarot : The Sage | G17: Yes | H17: Yes | I17: Also appears in the Main Hall, where she grants Mirror Kneel (MC_CharacterDataModificator_Eleanor)
A18: Trevor Belmont (NPC) | B18: Choir | C18: ND - Choir | D18: Arcane Whip AND Holy Light AND Aerial Rush AND Smash AND Double Jump AND The Shadow Confronted AND Brauner's Paintbrush AND Tarot : The Artist | E18: Double Jump | F18: Whip : Vampire Killer | G18: No | H18: No | I18: In the room right behind Death 2; the end of that fight normally takes you there automatically
A19: Jeanne d'Arc 2 | B19: Courage of Gabriel | C19: ND - Courage of Gabriel | D19: Arcane Whip AND Holy Light AND Aerial Rush AND Smash AND Double Jump AND Tarot : The Warrior AND The Shadow Confronted AND Brauner's Paintbrush AND Tarot : The Artist | E19: X | F19: Virtue of Courage | G19: No | H19: Yes
A20: Doppelganger | B20: Gallery of the Four Virtues | C20: ND - Gallery of the Four Virtues | D20: Arcane Whip AND Holy Light AND Aerial Rush AND Smash AND Double Jump AND The Four Virtues AND The Shadow Confronted AND Brauner's Paintbrush AND Tarot : The Artist | E20: X | F20: Tarot : The Self | G20: Yes | H20: Yes
A21: Isaac 2 | B21: Heart of the Clock | C21: CT - Heart of the Clock | D21: Arcane Whip AND Holy Light AND Aerial Rush AND Smash AND Double Jump AND The Shadow Confronted AND Tarot : The Shadow (Soul Harvest, Death Trap) | E21: X | F21: Tarot : The Zealot | G21: Yes | H21: No | I21: In Clock Tower (Upper) per the other xlsx
A22: Dracula 1 | B22: Court of the Night | C22: MQ - Court of the Night | D22: Arcane Whip AND Holy Light AND Aerial Rush AND Smash AND Double Jump AND The Shadow Confronted AND Tarot : The Shadow (Soul Harvest, Death Trap) | E22: X | F22: X | G22: No | H22: Yes
A23: Dracula 2 | B23: Castle Rooftops | C23: MQ - Castle Rooftops | D23: Arcane Whip AND Holy Light AND Aerial Rush AND Smash AND Double Jump AND The Shadow Confronted AND Tarot : The Shadow (Soul Harvest, Death Trap) | E23: X | F23: X | G23: No | H23: Yes

Sheet Endings
A1: 3 possible goals in the YAML: Bad / Neutral / True. A finished save can be continued to reach another ending.
A2: Ending | B2: Region / room | C2: Exact conditions | D2: Required items | E2: What prevents it | F2: Notes
A3: Bad Ending | B3: MQ - Master's Quarter (Bad Ending), entered from the Clock Tower | C3: Enter Master's Quarter from the Clock Tower without having disarmed the Death Trap with The Shadow (Soul Harvest) | D3: Main Hall access (Arcane Whip AND The Shadow Confronted) AND Arcane Whip AND Holy Light | E3: Having disarmed the Death Trap with The Shadow | F3: Can be re-triggered at any time with The Shadow; no need to block the room
A4: Neutral Ending | B4: MQ - Master's Quarter (Dracula), entered from Clock Tower (Upper) | C4: Defeat the final boss and do nothing during the scripted window | D4: Clock Tower (Upper): Tarot : The Shadow AND Arcane Whip AND Double Jump AND Smash AND Aerial Rush (+ Main Hall access) | E4: Using The Self during the window
A5: True Ending | B5: MQ - Master's Quarter (Dracula) | C5: Defeat the final boss, then use the power of The Self during the scripted window | D5: Neutral Ending route AND Doppelganger (4 Virtues: The Warrior, The Whisperer, The Judge, The Sage + Notre-Dame access) AND Tarot : The Cursed AND Tarot : The Self (Absolution) | F5: The Self = upgrade of The Cursed (4 Virtue trials + Doppelganger)

Sheet ID Range
A1: One range of 1000 IDs per category. Blue values are editable, range ends recompute.
A2: Category | B2: Start (items) | C2: End (items) | D2: Start (locations) | E2: End (locations) | F2: Notes
A3: Relic | B3: 7001000 | C3: =B3+999 -> 7001999 | D3: 7101000 | E3: =D3+999 -> 7101999
A4: Weapon | B4: 7002000 | C4: =B4+999 -> 7002999 | D4: 7102000 | E4: =D4+999 -> 7102999 | F4: Progressive weapons: 7002029+
A5: Clue | B5: 7003000 | C5: =B5+999 -> 7003999 | D5: 7103000 | E5: =D5+999 -> 7103999
A6: Tarot Cards | B6: 7004000 | C6: =B6+999 -> 7004999 | D6: 7104000 | E6: =D6+999 -> 7104999
A7: Augmentation | B7: 7005000 | C7: =B7+999 -> 7005999 | D7: 7105000 | E7: =D7+999 -> 7105999
A8: Work of Mercy upgrade | B8: 7006000 | C8: =B8+999 -> 7006999 | D8: 7106000 | E8: =D8+999 -> 7106999
A9: Key Item / Skill | B9: 7007000 | C9: =B9+999 -> 7007999 | D9: 7107000 | E9: =D9+999 -> 7107999 | F9: Progressive Virtue 7007015; The Shadow Confronted, Mirror Kneel, 3 Mammon eyes 7007016-7007020 (locations 7107015-7107019)
A10: EXP Statue | B10: 7008000 | C10: =B10+999 -> 7008999 | D10: 7108000 | E10: =D10+999 -> 7108999
A11: Trap | B11: 7009000 | C11: =B11+999 -> 7009999 | F11: No locations
A12: Events (endings, victory) | D12: 7109000 | E12: =D12+999 -> 7109999 | F12: Can also use ID None

Sheet Works of Mercy
A1: One row per Work of Mercy. Each upgrade becomes a fixed item; it can arrive before its card.
A2: Card | B2: Challenge (condition) | C2: Upgrade 1 | D2: Upgrade 2 | E2: Upgrade 3 | F2: Location (name) | G2: Notes
A3: Tarot : The Cursed | B3: Hit 20 times with this spell. | C3: Fires a bigger fireball that slightly pushes back its target. | D3: X | E3: X | F3: WOM - Cursed Flame 1
A4: Tarot : The Self | B4: Kill 4 enemies with one cast of this spell, 5 times. | C4: If the spell is cast while Rose is at full health, deals 50% more damage. | D4: If the spell hits only one target, ignites it. | E4: If the spell kills at least 4 enemies, heals Rose back to full health. | F4: WOM - Absolution 1
A5: Tarot : The Self | B5: Explore 85% of the whole map. | C5: // | D5: // | E5: // | F5: WOM - Absolution 2 | G5: Can be completed before getting the card
A6: Tarot : The Self | B6: Heal back to full life using this spell 10 times. | C6: // | D6: // | E6: // | F6: WOM - Absolution 3
A7: Tarot : The Fallen | B7: Find 3 different whip-type weapons. | C7: You can throw a second cross. | D7: The cross inflicts more damage the farther it is from Rose. | E7: Catching the returning cross lets Rose regain 10% of the spell's mana cast for each time an enemy was hit, up to a maximum of 60%. | F7: WOM - Holy Cross 1 | G7: Can be completed before getting the card
A8: Tarot : The Fallen | B8: Kill 5 enemies with the same cross (not necessarily at the same time). | C8: // | D8: // | E8: // | F8: WOM - Holy Cross 2
A9: Tarot : The Fallen | B9: Kill 10 enemies with a whip attack. | C9: // | D9: // | E9: // | F9: WOM - Holy Cross 3
A10: Tarot : The Warrior | B10: Successfully parry 15 attacks with the Holy Light. | C10: Regain 25% of the spell's mana cost for each enemy hit by the central explosion, starting with the second enemy. | D10: Enemies hit by Joan's spell are thrown high in the air. | E10: Hitting an enemy with a weapon prolongs the fire on them. | F10: WOM - Infernal Pyre 1
A11: Tarot : The Warrior | B11: Reach a sacred place so Joan can pray. | C11: // | D11: // | E11: // | F11: WOM - Infernal Pyre 2 | G11: Can be completed before getting the card
A12: Tarot : The Warrior | B12: Set 5 enemies on fire at the same time. | C12: // | D12: // | E12: // | F12: WOM - Infernal Pyre 3
A13: Tarot : The Prophetess | B13: Petrify an enemy carrying a shield with Medusa’s Spell. Not again, Perseus! | C13: Killing a petrified enemy restores a quantity of mana equivalent to half the cost of Medusa's spell. | D13: The closer the targets affected by this spell are to Rose, the longer they remain petrified, and the more hits it takes to break the petrification. | E13: X | F13: WOM - Petrifying Gaze 1
A14: Tarot : The Prophetess | B14: Kill 25 enemies from fall damage directly after petrifying them in the air. | C14: // | D14: // | E14: // | F14: WOM - Petrifying Gaze 2
A15: Tarot : The Builder | B15: Kill 3 enemies with one fist. | C15: The fist deals 75% more damage to enemies suffering from control effects. | D15: The earthquake is more powerful and unleashes 1 second later. | E15: The fist is covered in damage-dealing spikes that hit enemies even after hitting the ground. | F15: WOM - Fist of Talos 1
A16: Tarot : The Builder | B16: Kill 10 airborne enemies with a fist as it falls down. | C16: // | D16: // | E16: // | F16: WOM - Fist of Talos 2
A17: Tarot : The Builder | B17: Kill 15 enemies with the smash. | C17: // | D17: // | E17: // | F17: WOM - Fist of Talos 3
A18: Tarot : The Artist | B18: Kill 30 enemies with the Gargoyle Dive. | C18: Summons an additional Gargoyle | D18: Rose heals every time the Gargoyle's fire ball hits an enemy. | E18: Killing at least one enemy with the Gargoyle Dive prevents the Gargoyle's destruction. | F18: WOM - Masterpiece 1
A19: Tarot : The Artist | B19: Cause 5 enemies to fall to their death with the Gargoyle Summoning Stone. | C19: // | D19: // | E19: // | F19: WOM - Masterpiece 2
A20: Tarot : The Artist | B20: Find all the secret zones in the Main Hall. | C20: // | D20: // | E20: // | F20: WOM - Masterpiece 3 | G20: Can be completed before getting the card
A21: Tarot : The Occultist | B21: Kill 25 enemies from bleed-effect damage. | C21: Applying the bleeding effect to an already bleeding enemy deals instant damage to it. | D21: Heals Rose 2% of her max health every time an enemy dies from bleeding. | E21: Bleeding enemies are slower and deal 25% less damage to Rose. | F21: WOM - Blood Spikes 1
A22: Tarot : The Occultist | B22: Find 2 different dual blade-type weapons. | C22: // | D22: // | E22: // | F22: WOM - Blood Spikes 2 | G22: Can be completed before getting the card
A23: Tarot : The Occultist | B23: Cause an enemy to bleed continuously for 10 seconds. | C23: // | D23: // | E23: // | F23: WOM - Blood Spikes 3
A24: Tarot : The Shadow | B24: Complete the hidden puzzle in Notre Dame. | C24: If this spell only hits one enemy, Rose heals 4% of her maximum health. | D24: If a sickle kills an enemy, it splits into 4 new sickles. | E24: Each sickle that hits an enemy restores 25% of the spell's mana cost. | F24: WOM - Soul Harvest 1 | G24: Can be completed before getting the card
A25: Tarot : The Shadow | B25: Kill 44 skeletons (of any sort). | C25: // | D25: // | E25: // | F25: WOM - Soul Harvest 2
A26: Tarot : The Shadow | B26: Kill 4 enemies with the same cast of Death’s spell. | C26: // | D26: // | E26: // | F26: WOM - Soul Harvest 3
A27: Tarot : The Miser | B27: Have the wheel spin for 15 seconds without interruption. | C27: The spell can be cast using health if Rose does not have enough mana and will deal 50% more damage. | D27: Mammon's spell deals increased damage each time it is cast. This bonus resets if the spell is not recast while active. | E27: Every time the player recasts the spell, there is a 1/8 chance of triggering a random effect. | F27: WOM - Wheel of Chaos 1
A28: Tarot : The Miser | B28: Kill 5 different enemies with one wheel. | C28: // | D28: // | E28: // | F28: WOM - Wheel of Chaos 2
A29: Tarot : The Miser | B29: Spend 1000 mana points on recasts of this spell. | C29: // | D29: // | E29: // | F29: WOM - Wheel of Chaos 3
A30: Tarot : The Whisperer | B30: Kill 25 enemies by breaking them out of freeze. | C30: At the end of the spell effect, a wave of frost bursts around Rose that freezes enemies within a radius of 5 meters. | D30: Passing through an enemy increases your speed by 10% for a maximum of 5 times. Can only trigger once on the same enemy. | E30: X | F30: WOM - Freezing Path 1
A31: Tarot : The Whisperer | B31: Pass through 5 enemies in 3 seconds. | C31: // | D31: // | E31: // | F31: WOM - Freezing Path 2
A32: Tarot : The Zealot | B32: Kill 20 enemies while in slow motion. | C32: The time slow effect is longer. | D32: Creates a bigger explosion if Rose dives from a high enough position. | E32: X | F32: WOM - Chronomantic Dive 1
A33: Tarot : The Zealot | B33: Explore all rooms of Clock Tower. | C33: // | D33: // | E33: // | F33: WOM - Chronomantic Dive 2 | G33: Can be completed before getting the card
A34: Tarot : The Temptress | B34: Drain an enemy for 5 seconds straight without interruption. | C34: The drain deals bonus damage if Rose is at full health when it ticks. | D34: Getting hit while holding this spell doesn't interrupt it. | E34: The spell targets the 2 nearest enemies instead of just one. | F34: WOM - Life Drain 1
A35: Tarot : The Temptress | B35: Explore all rooms of Hall of Mirrors. | C35: // | D35: // | E35: // | F35: WOM - Life Drain 2 | G35: Can be completed before getting the card
A36: Tarot : The Temptress | B36: Kill 25 enemies with the life drain. | C36: // | D36: // | E36: // | F36: WOM - Life Drain 3
A37: Tarot : The Brittle King | B37: Absorb an attack that would otherwise be fatal thanks to Arthur's spell. | C37: The spell's magic shield can absorb 1 additional attacks before it breaks. | D37: Each time Rose takes damage (with or without an active magic shield), a shard of glass is launched at the nearest enemy. | E37: When Rose is struck during an attack damage received is reduced by 50% and her attack continues uninterrupted. | F37: WOM - Stained-Glass Shield 1
A38: Tarot : The Brittle King | B38: Kill 25 Haunted Armor. | C38: // | D38: // | E38: // | F38: WOM - Stained-Glass Shield 2
A39: Tarot : The Brittle King | B39: Kill 3 enemies with a single attack. | C39: // | D39: // | E39: // | F39: WOM - Stained-Glass Shield 3
A40: Tarot : The Judge | B40: Chain 4 enemies at once. | C40: Chained enemies are also rendered incapable of performing any action. | D40: Killing a chained target chains a nearby target. | E40: Chaining an enemy with less than 20% of their maximum health instantly kills them. | F40: WOM - Chains of Justice 1
...

Sheet Enemies
A1: For the future enemy randomizer option.
A2: Enemy | B2: Areas where it appears | C2: Never randomized? ▼ | D2: Why | E2: Notes
A3: (name) | B3: Area, Area | C3: No

Sheet Status
A1: For traps.
A2: Status effect | B2: In-game effect | C2: Duration (s) | D2: Good trap? ▼ | E2: Default weight (0-100) | F2: Notes
A3: (e.g. Poison) | B3: (gradual HP loss) | D3: Yes
A4: Burn | B4: Drains 1% of HP, 5 times per second for 3 seconds, 15% total. Cannot kill | C4: 3 | D4: Yes | E4: 22
A5: Bleed | B5: Drains 1% of HP, twice per second for 8 seconds, 16% total. Cannot kill | C5: 8 | D5: Yes | E5: 22
A6: Petrify | B6: Turns Rose to stone for 3 seconds max. Reduced by mashing button, each press of a button cutting 0.4 seconds | C6: 3 | D6: Yes | E6: 22
A7: Turned to gold | B7: Turns Rose to gold for 4 seconds. Afterwards 1 second of protection from it happening again | C7: 4 | D7: No | E7: 6
A8: Stun | B8: Rose is stunned for 3 seconds | C8: 3 | D8: No | E8: 6
A9: Plague | B9: Every hit deals 15% of HP bonus damage | C9: 7 | D9: Yes | E9: 22

Sheet Progressive Weapons
A1: Unlock order when « Progressive Weapons » is on (tier 1 = received first).
A2: Group (weapon type) | B2: Tier | C2: Weapon | D2: Vanilla location | E2: Notes
A3: (e.g. Whips) | B3: 1 | C3: (weakest weapon of the group)
A4: Whip | B4: 1 | C4: Whip | D4: CoP - Hall of the Fallen Angels : Gold Chest | E4: Whip group = progression: any whip breaks the Hall of Mirrors seals
A5: Whip | B5: 2 | C5: Thorn Whip | D5: L - Fine Arts Shelves : Gold Chest
A6: Whip | B6: 3 | C6: Morning Star | D6: MH - Inner Courtyard : Gold Chest
A7: Whip | B7: 4 | C7: Vampire Killer | D7: ND - Deacon's Quarter : Trevor Belmont
A8: OHSword | B8: 1 | C8: Longsword | D8: X | E8: Starting weapon
A9: OHSword | B9: 2 | C9: Bastard Sword | D9: PS - Justice District Sewers : Gold Chest
A10: OHSword | B10: 3 | C10: Joyeuse | D10: ND - Path of the Penitent : Gold Chest
A11: OHSword | B11: 4 | C11: Valmanway | D11: PS - Palace of Justice : Saint Louis
A12: THSword | B12: 1 | C12: Burnt Sword of Fierbois | D12: PS - Roof of the Tower : Jeanne d'Arc Defeated
A13: THSword | B13: 2 | C13: Claymore | D13: CT - The Way of the Fist : Gold Chest
A14: THSword | B14: 3 | C14: Durandal | D14: L - Lisa's Laboratory : Gold Chest
A15: THSword | B15: 4 | C15: Excalibur | D15: ND - Chapel : Arthur Defeated
A16: Dual Blades | B16: 1 | C16: Pair of Longswords | D16: CoP - Crossroads of the Dead : Gold Chest
A17: Dual Blades | B17: 2 | C17: Rapiers | D17: MH - Watch Tower : Gold Chest
A18: Dual Blades | B18: 3 | C18: Almace and Hauteclaire | D18: HIC - Flooded Crypt : Gold Chest
A19: Dual Blades | B19: 4 | C19: War and Famine | D19: ND - Great Organ Room : Gold Chest
A20: Spear | B20: 1 | C20: Lance | D20: HIC - Fountain of the Innocents : Gold Chest
... A31: Sword and Shield | B31: 4 | C31: Alucard's Sword and Shield | D31: MH - Alucard's Tower : Gold Chest
